Workbook

Sheet Summary
A1: Q1 2026 cash receipts reconciliation: bank, AR subledger and GL
A2: Synthetic data. Matching was done in SQL (sql/ folder); this workbook reports the result.
A3: Blue = value taken from the SQL run. Black = formula. Yellow cells on the Exceptions sheet (Analyst status / notes) are for the reviewer to fill in.
A5: Matching settings used
A6: Amount tolerance | B6: 1 | C6: Largest amount difference still treated as a match (bank fees, rounding).
A7: Date tolerance (days) | B7: 7 | C7: Largest date spread across systems before a match is reported as a timing gap.
A8: Reference-link window (days) | B8: 45 | C8: How far apart two rows with the same reference may be and still be linked.
A9: High severity from | B9: 5000 | C9: Exposure at or above this amount.
A10: Medium severity from | B10: 1000 | C10: Exposure at or above this amount.
A12: Population: what cleared without review
A13: System | B13: Rows | C13: Cleared | D13: For review | E13: Cleared %
A14: Bank statement | B14: 1471 | C14: 1387 | D14: =B14-C14 | E14: =C14/B14
A15: AR subledger | B15: 1482 | C15: 1387 | D15: =B15-C15 | E15: =C15/B15
A16: General ledger | B16: 1472 | C16: 1387 | D16: =B16-C16 | E16: =C16/B16
A17: All systems | B17: =SUM(B14:B16) | C17: =SUM(C14:C16) | D17: =SUM(D14:D16) | E17: =C17/B17
A20: Exceptions by type
A21: Type | B21: Count | C21: Exposure ($) | D21: High severity | E21: Avg age (days)
A22: Missing in GL | B22: =COUNTIF(Exceptions!$B$2:$B$131,A22) | C22: =SUMIF(Exceptions!$B$2:$B$131,A22,Exceptions!$M$2:$M$131) | D22: =COUNTIFS(Exceptions!$B$2:$B$131,A22,Exceptions!$C$2:$C$131,"High") | E22: =IF(B22=0,0,SUMIF(Exceptions!$B$2:$B$131,A22,Exceptions!$O$2:$O$131)/B22)
A23: Missing in bank | B23: =COUNTIF(Exceptions!$B$2:$B$131,A23) | C23: =SUMIF(Exceptions!$B$2:$B$131,A23,Exceptions!$M$2:$M$131) | D23: =COUNTIFS(Exceptions!$B$2:$B$131,A23,Exceptions!$C$2:$C$131,"High") | E23: =IF(B23=0,0,SUMIF(Exceptions!$B$2:$B$131,A23,Exceptions!$O$2:$O$131)/B23)
A24: Timing gap | B24: =COUNTIF(Exceptions!$B$2:$B$131,A24) | C24: =SUMIF(Exceptions!$B$2:$B$131,A24,Exceptions!$M$2:$M$131) | D24: =COUNTIFS(Exceptions!$B$2:$B$131,A24,Exceptions!$C$2:$C$131,"High") | E24: =IF(B24=0,0,SUMIF(Exceptions!$B$2:$B$131,A24,Exceptions!$O$2:$O$131)/B24)
A25: Amount mismatch | B25: =COUNTIF(Exceptions!$B$2:$B$131,A25) | C25: =SUMIF(Exceptions!$B$2:$B$131,A25,Exceptions!$M$2:$M$131) | D25: =COUNTIFS(Exceptions!$B$2:$B$131,A25,Exceptions!$C$2:$C$131,"High") | E25: =IF(B25=0,0,SUMIF(Exceptions!$B$2:$B$131,A25,Exceptions!$O$2:$O$131)/B25)
A26: Duplicate posting | B26: =COUNTIF(Exceptions!$B$2:$B$131,A26) | C26: =SUMIF(Exceptions!$B$2:$B$131,A26,Exceptions!$M$2:$M$131) | D26: =COUNTIFS(Exceptions!$B$2:$B$131,A26,Exceptions!$C$2:$C$131,"High") | E26: =IF(B26=0,0,SUMIF(Exceptions!$B$2:$B$131,A26,Exceptions!$O$2:$O$131)/B26)
A27: Missing in AR | B27: =COUNTIF(Exceptions!$B$2:$B$131,A27) | C27: =SUMIF(Exceptions!$B$2:$B$131,A27,Exceptions!$M$2:$M$131) | D27: =COUNTIFS(Exceptions!$B$2:$B$131,A27,Exceptions!$C$2:$C$131,"High") | E27: =IF(B27=0,0,SUMIF(Exceptions!$B$2:$B$131,A27,Exceptions!$O$2:$O$131)/B27)
A28: Bank credit only | B28: =COUNTIF(Exceptions!$B$2:$B$131,A28) | C28: =SUMIF(Exceptions!$B$2:$B$131,A28,Exceptions!$M$2:$M$131) | D28: =COUNTIFS(Exceptions!$B$2:$B$131,A28,Exceptions!$C$2:$C$131,"High") | E28: =IF(B28=0,0,SUMIF(Exceptions!$B$2:$B$131,A28,Exceptions!$O$2:$O$131)/B28)
A29: AR application only | B29: =COUNTIF(Exceptions!$B$2:$B$131,A29) | C29: =SUMIF(Exceptions!$B$2:$B$131,A29,Exceptions!$M$2:$M$131) | D29: =COUNTIFS(Exceptions!$B$2:$B$131,A29,Exceptions!$C$2:$C$131,"High") | E29: =IF(B29=0,0,SUMIF(Exceptions!$B$2:$B$131,A29,Exceptions!$O$2:$O$131)/B29)
A30: GL entry only | B30: =COUNTIF(Exceptions!$B$2:$B$131,A30) | C30: =SUMIF(Exceptions!$B$2:$B$131,A30,Exceptions!$M$2:$M$131) | D30: =COUNTIFS(Exceptions!$B$2:$B$131,A30,Exceptions!$C$2:$C$131,"High") | E30: =IF(B30=0,0,SUMIF(Exceptions!$B$2:$B$131,A30,Exceptions!$O$2:$O$131)/B30)
A31: Ambiguous match | B31: =COUNTIF(Exceptions!$B$2:$B$131,A31) | C31: =SUMIF(Exceptions!$B$2:$B$131,A31,Exceptions!$M$2:$M$131) | D31: =COUNTIFS(Exceptions!$B$2:$B$131,A31,Exceptions!$C$2:$C$131,"High") | E31: =IF(B31=0,0,SUMIF(Exceptions!$B$2:$B$131,A31,Exceptions!$O$2:$O$131)/B31)
A32: Total | B32: =SUM(B22:B31) | C32: =SUM(C22:C31) | D32: =SUM(D22:D31) | E32: =AVERAGE(Exceptions!$O$2:$O$131)
A33: Check: type counts equal rows on Exceptions sheet | B33: =IF(B32=COUNTA(Exceptions!$A$2:$A$131),"OK","CHECK")
A36: Exceptions by severity
A37: Severity | B37: Count | C37: Exposure ($)
A38: High | B38: =COUNTIF(Exceptions!$C$2:$C$131,A38) | C38: =SUMIF(Exceptions!$C$2:$C$131,A38,Exceptions!$M$2:$M$131)
A39: Medium | B39: =COUNTIF(Exceptions!$C$2:$C$131,A39) | C39: =SUMIF(Exceptions!$C$2:$C$131,A39,Exceptions!$M$2:$M$131)
A40: Low | B40: =COUNTIF(Exceptions!$C$2:$C$131,A40) | C40: =SUMIF(Exceptions!$C$2:$C$131,A40,Exceptions!$M$2:$M$131)
A42: Review progress (driven by the Analyst status column)
A43: Status | B43: Count | C43: Exposure ($)
A44: Open | B44: =COUNTIF(Exceptions!$Q$2:$Q$131,A44) | C44: =SUMIF(Exceptions!$Q$2:$Q$131,A44,Exceptions!$M$2:$M$131)
A45: In review | B45: =COUNTIF(Exceptions!$Q$2:$Q$131,A45) | C45: =SUMIF(Exceptions!$Q$2:$Q$131,A45,Exceptions!$M$2:$M$131)
A46: Resolved | B46: =COUNTIF(Exceptions!$Q$2:$Q$131,A46) | C46: =SUMIF(Exceptions!$Q$2:$Q$131,A46,Exceptions!$M$2:$M$131)
A47: Not an issue | B47: =COUNTIF(Exceptions!$Q$2:$Q$131,A47) | C47: =SUMIF(Exceptions!$Q$2:$Q$131,A47,Exceptions!$M$2:$M$131)
...

Sheet Exceptions
A1: Exception ID | B1: Type | C1: Severity | D1: Found in | E1: Reference | F1: Customer | G1: Bank ID | H1: AR ID | I1: GL ID | J1: Bank amount | K1: AR amount | L1: GL amount | M1: Exposure ($) | N1: Date spread (days) | O1: Age (days) | P1: Review note | Q1: Analyst status | R1: Analyst notes
A2: E0001 | B2: Timing gap | C2: High | D2: BANK + SL + GL | E2: 10214 | F2: C034 | G2: B000168 | H2: S000174 | I2: G000637 | J2: 40115.5 | K2: 40115.5 | L2: 40115.5 | M2: 40115.5 | N2: 28 | O2: 79 | P2: Ties across all three systems but dates span 28 days (tolerance 7). Pending analyst review.
A3: E0002 | B3: Duplicate posting | C3: High | D3: GL | E3: 11112 | I3: G000866 | L3: 27120.68 | M3: 27120.68 | N3: 1 | O3: 39 | P3: Same reference and amount already posted once in GL (G000845). Pending analyst review.
A4: E0003 | B4: Missing in AR | C4: High | D4: BANK + GL | E4: 11053 | G4: B000815 | I4: G000818 | J4: 26238.07 | L4: 26238.07 | M4: 26238.07 | N4: 2 | O4: 44 | P4: In bank and GL; no AR subledger application found. Pending analyst review.
A5: E0004 | B5: Missing in GL | C5: High | D5: BANK + SL | E5: 10989 | F5: C032 | G5: B000323 | H5: S000314 | J5: 25585.12 | K5: 25585.12 | M5: 25585.12 | N5: 0 | O5: 70 | P5: In bank and AR subledger; no GL entry within tolerance. Pending analyst review.
A6: E0005 | B6: Missing in bank | C6: High | D6: SL + GL | E6: 10784 | F6: C018 | H6: S000481 | I6: G000448 | K6: 23313.29 | L6: 23313.29 | M6: 23313.29 | N6: 0 | O6: 61 | P6: In AR subledger and GL; no matching bank credit found. Pending analyst review.
A7: E0006 | B7: Duplicate posting | C7: High | D7: SL | E7: 10953 | F7: C042 | H7: S000298 | K7: 17900.17 | M7: 17900.17 | N7: 2 | O7: 71 | P7: Same reference and amount already posted once in SL (S000274). Pending analyst review.
A8: E0007 | B8: Timing gap | C8: High | D8: BANK + SL + GL | E8: 10868 | F8: C027 | G8: B000229 | H8: S000237 | I8: G000596 | J8: 16088.16 | K8: 16088.16 | L8: 16088.16 | M8: 16088.16 | N8: 23 | O8: 76 | P8: Ties across all three systems but dates span 23 days (tolerance 7). Pending analyst review.
A9: E0008 | B9: Missing in bank | C9: High | D9: SL + GL | E9: 10480 | F9: C019 | H9: S001273 | I9: G001251 | K9: 15841.22 | L9: 15841.22 | M9: 15841.22 | N9: 0 | O9: 19 | P9: In AR subledger and GL; no matching bank credit found. Pending analyst review.
A10: E0009 | B10: Missing in bank | C10: High | D10: SL + GL | E10: 10288 | F10: C038 | H10: S000967 | I10: G000954 | K10: 12177.35 | L10: 12177.35 | M10: 12177.35 | N10: 0 | O10: 35 | P10: In AR subledger and GL; no matching bank credit found. Pending analyst review.
A11: E0010 | B11: Missing in bank | C11: High | D11: SL + GL | E11: 10540 | F11: C018 | H11: S000084 | I11: G000076 | K11: 12095.16 | L11: 12095.16 | M11: 12095.16 | N11: 1 | O11: 83 | P11: In AR subledger and GL; no matching bank credit found. Pending analyst review.
A12: E0011 | B12: Missing in GL | C12: High | D12: BANK + SL | E12: 10326 | F12: C059 | G12: B000425 | H12: S000420 | J12: 12054.05 | K12: 12054.05 | M12: 12054.05 | N12: 1 | O12: 65 | P12: In bank and AR subledger; no GL entry within tolerance. Pending analyst review.
A13: E0012 | B13: Missing in GL | C13: High | D13: BANK + SL | E13: 10329 | F13: C050 | G13: B000547 | H13: S000588 | J13: 11793.65 | K13: 11793.65 | M13: 11793.65 | N13: 2 | O13: 57 | P13: In bank and AR subledger; no GL entry within tolerance. Pending analyst review.
A14: E0013 | B14: Duplicate posting | C14: High | D14: SL | E14: 11139 | F14: C040 | H14: S001077 | K14: 10864.06 | M14: 10864.06 | N14: 1 | O14: 29 | P14: Same reference and amount already posted once in SL (S001052). Pending analyst review.
A15: E0014 | B15: Timing gap | C15: High | D15: BANK + SL + GL | E15: 10445 | F15: C027 | G15: B000914 | H15: S000948 | I15: G001131 | J15: 10193.49 | K15: 10193.49 | L15: 10193.49 | M15: 10193.49 | N15: 13 | O15: 38 | P15: Ties across all three systems but dates span 13 days (tolerance 7). Pending analyst review.
A16: E0015 | B16: Missing in GL | C16: High | D16: BANK + SL | E16: 10933 | F16: C035 | G16: B001386 | H16: S001371 | J16: 9954.2 | K16: 9954.2 | M16: 9954.2 | N16: 0 | O16: 13 | P16: In bank and AR subledger; no GL entry within tolerance. Pending analyst review.
A17: E0016 | B17: Duplicate posting | C17: High | D17: SL | E17: 10993 | F17: C004 | H17: S000310 | K17: 9667.11 | M17: 9667.11 | N17: 0 | O17: 71 | P17: Same reference and amount already posted once in SL (S000307). Pending analyst review.
A18: E0017 | B18: Missing in GL | C18: High | D18: BANK + SL | E18: 10912 | F18: C060 | G18: B000576 | H18: S000597 | J18: 9081.19 | K18: 9081.19 | M18: 9081.19 | N18: 1 | O18: 55 | P18: In bank and AR subledger; no GL entry within tolerance. Pending analyst review.
A19: E0018 | B19: Missing in bank | C19: High | D19: SL + GL | E19: 10365 | F19: C042 | H19: S000016 | I19: G000009 | K19: 8848.43 | L19: 8848.43 | M19: 8848.43 | N19: 0 | O19: 87 | P19: In AR subledger and GL; no matching bank credit found. Pending analyst review.
A20: E0019 | B20: Missing in bank | C20: High | D20: SL + GL | E20: 10090 | F20: C054 | H20: S000465 | I20: G000438 | K20: 7840.34 | L20: 7840.34 | M20: 7840.34 | N20: 0 | O20: 62 | P20: In AR subledger and GL; no matching bank credit found. Pending analyst review.
A21: E0020 | B21: Timing gap | C21: High | D21: BANK + SL + GL | E21: 10269 | F21: C034 | G21: B000179 | H21: S000215 | I21: G000579 | J21: 6171.84 | K21: 6171.84 | L21: 6171.84 | M21: 6171.84 | N21: 26 | O21: 79 | P21: Ties across all three systems but dates span 26 days (tolerance 7). Pending analyst review.
A22: E0021 | B22: Missing in GL | C22: High | D22: BANK + SL | E22: 10039 | F22: C041 | G22: B000783 | H22: S000827 | J22: 6165.65 | K22: 6165.65 | M22: 6165.65 | N22: 3 | O22: 46 | P22: In bank and AR subledger; no GL entry within tolerance. Pending analyst review.
A23: E0022 | B23: GL entry only | C23: High | D23: GL | E23: 10544 | I23: G000865 | L23: 5619.59 | M23: 5619.59 | N23: 0 | O23: 39 | P23: GL entry with no matching bank credit or AR application. Pending analyst review.
A24: E0023 | B24: Timing gap | C24: High | D24: BANK + SL + GL | E24: 11063 | F24: C019 | G24: B000155 | H24: S000166 | I24: G000483 | J24: 5495.96 | K24: 5495.96 | L24: 5495.97 | M24: 5495.96 | N24: 20 | O24: 80 | P24: Ties across all three systems but dates span 20 days (tolerance 7). Pending analyst review.
A25: E0024 | B25: Timing gap | C25: High | D25: BANK + SL + GL | E25: 10318 | F25: C043 | G25: B000658 | H25: S000639 | I25: G001001 | J25: 5240.76 | K25: 5240.76 | L25: 5240.76 | M25: 5240.76 | N25: 20 | O25: 52 | P25: Ties across all three systems but dates span 20 days (tolerance 7). Pending analyst review.
A26: E0025 | B26: Ambiguous match | C26: High | D26: BANK | G26: B000976 | J26: 5000 | M26: 5000 | N26: 0 | O26: 35 | P26: Several possible counterparts on amount and date; deliberately not auto-matched. Pending analyst review.
A27: E0026 | B27: Missing in bank | C27: High | D27: SL + GL | E27: 10536 | F27: C059 | H27: S000936 | I27: G000908 | K27: 5000 | L27: 5000 | M27: 5000 | N27: 0 | O27: 37 | P27: In AR subledger and GL; no matching bank credit found. Pending analyst review.
A28: E0027 | B28: Missing in bank | C28: High | D28: SL + GL | E28: 10566 | F28: C016 | H28: S000965 | I28: G000948 | K28: 5000 | L28: 5000 | M28: 5000 | N28: 0 | O28: 35 | P28: In AR subledger and GL; no matching bank credit found. Pending analyst review.
A29: E0028 | B29: Missing in GL | C29: Medium | D29: BANK + SL | E29: 11125 | F29: C054 | G29: B000133 | H29: S000157 | J29: 4850.79 | K29: 4850.79 | M29: 4850.79 | N29: 2 | O29: 81 | P29: In bank and AR subledger; no GL entry within tolerance. Pending analyst review.
A30: E0029 | B30: Timing gap | C30: Medium | D30: BANK + SL + GL | E30: 10383 | F30: C004 | G30: B001467 | H30: S001479 | I30: G001471 | J30: 4764.95 | K30: 4765.3 | L30: 4765.3 | M30: 4765.3 | N30: 23 | O30: 9 | P30: Ties across all three systems but dates span 23 days (tolerance 7). Pending analyst review.
A31: E0030 | B31: Amount mismatch | C31: Medium | D31: BANK + SL + GL | E31: 10033 | F31: C048 | G31: B001084 | H31: S001074 | I31: G001047 | J31: 11645.51 | K31: 16145.51 | L31: 11645.51 | M31: 4500 | N31: 0 | O31: 29 | P31: Reference ties across all three systems but amounts differ by $4500.00 (tolerance $1.00). Pending analyst review.
A32: E0031 | B32: Missing in AR | C32: Medium | D32: BANK + GL | E32: 11227 | G32: B001465 | I32: G001461 | J32: 4482.13 | L32: 4482.13 | M32: 4482.13 | N32: 3 | O32: 9 | P32: In bank and GL; no AR subledger application found. Pending analyst review.
A33: E0032 | B33: Timing gap | C33: Medium | D33: BANK + SL + GL | E33: 11351 | F33: C052 | G33: B001159 | H33: S001209 | I33: G001468 | J33: 4439.22 | K33: 4439.22 | L33: 4439.23 | M33: 4439.22 | N33: 21 | O33: 25 | P33: Ties across all three systems but dates span 21 days (tolerance 7). Pending analyst review.
A34: E0033 | B34: Missing in AR | C34: Medium | D34: BANK + GL | E34: 11402 | G34: B000166 | I34: G000150 | J34: 4307.23 | L34: 4307.73 | M34: 4307.73 | N34: 0 | O34: 79 | P34: In bank and GL; no AR subledger application found. Pending analyst review.
A35: E0034 | B35: Timing gap | C35: Medium | D35: BANK + SL + GL | E35: 11311 | F35: C036 | G35: B000400 | H35: S000397 | I35: G000878 | J35: 4244.35 | K35: 4244.35 | L35: 4244.35 | M35: 4244.35 | N35: 28 | O35: 66 | P35: Ties across all three systems but dates span 28 days (tolerance 7). Pending analyst review.
A36: E0035 | B36: Duplicate posting | C36: Medium | D36: GL | E36: 10120 | I36: G001078 | L36: 4228.34 | M36: 4228.34 | N36: 0 | O36: 28 | P36: Same reference and amount already posted once in GL (G001066). Pending analyst review.
A37: E0036 | B37: Missing in GL | C37: Medium | D37: BANK + SL | E37: 10550 | F37: C060 | G37: B000171 | H37: S000156 | J37: 4154.48 | K37: 4154.48 | M37: 4154.48 | N37: 0 | O37: 79 | P37: In bank and AR subledger; no GL entry within tolerance. Pending analyst review.
A38: E0037 | B38: Bank credit only | C38: Medium | D38: BANK | E38: 11445 | G38: B001168 | J38: 4111.83 | M38: 4111.83 | N38: 0 | O38: 25 | P38: Bank credit with no matching AR or GL record. Pending analyst review.
A39: E0038 | B39: Duplicate posting | C39: Medium | D39: GL | E39: 10471 | I39: G000433 | L39: 4042.96 | M39: 4042.96 | N39: 1 | O39: 62 | P39: Same reference and amount already posted once in GL (G000416). Pending analyst review.
A40: E0039 | B40: Missing in AR | C40: Medium | D40: BANK + GL | E40: 10344 | G40: B001361 | I40: G001334 | J40: 3941.83 | L40: 3941.83 | M40: 3941.83 | N40: 0 | O40: 14 | P40: In bank and GL; no AR subledger application found. Pending analyst review.
...

Sheet Sensitivity
A1: Tolerance sensitivity: what each setting does to the exception queue
A2: Source: validate_against_ground_truth.py re-runs the SQL pipeline at each setting and scores it against the planted breaks. Values are outputs of that run (blue). Highlighted row = settings used.
A4: Amount tol. | B4: Date tol. (days) | C4: Rows cleared | D4: Exceptions | E4: Breaks missed | F4: False alarms | G4: Recall | H4: Precision
A5: 0 | B5: 2 | C5: 0.5695 | D5: 689 | E5: 4 | F5: 561 | G5: =(128-E5)/128 | H5: =IF(D5=0,1,1-F5/D5)
A6: 0 | B6: 5 | C6: 0.7932 | D6: 355 | E6: 4 | F6: 227 | G6: =(128-E6)/128 | H6: =IF(D6=0,1,1-F6/D6)
A7: 0 | B7: 7 | C7: 0.7953 | D7: 352 | E7: 4 | F7: 224 | G7: =(128-E7)/128 | H7: =IF(D7=0,1,1-F7/D7)
A8: 0 | B8: 10 | C8: 0.7953 | D8: 353 | E8: 5 | F8: 226 | G8: =(128-E8)/128 | H8: =IF(D8=0,1,1-F8/D8)
A9: 0.5 | B9: 2 | C9: 0.6536 | D9: 560 | E9: 0 | F9: 432 | G9: =(128-E9)/128 | H9: =IF(D9=0,1,1-F9/D9)
A10: 0.5 | B10: 5 | C10: 0.9064 | D10: 182 | E10: 0 | F10: 54 | G10: =(128-E10)/128 | H10: =IF(D10=0,1,1-F10/D10)
A11: 0.5 | B11: 7 | C11: 0.9105 | D11: 176 | E11: 0 | F11: 48 | G11: =(128-E11)/128 | H11: =IF(D11=0,1,1-F11/D11)
A12: 0.5 | B12: 10 | C12: 0.9112 | D12: 176 | E12: 2 | F12: 50 | G12: =(128-E12)/128 | H12: =IF(D12=0,1,1-F12/D12)
A13: 1 | B13: 2 | C13: 0.678 | D13: 522 | E13: 0 | F13: 394 | G13: =(128-E13)/128 | H13: =IF(D13=0,1,1-F13/D13)
A14: 1 | B14: 5 | C14: 0.9363 | D14: 136 | E14: 0 | F14: 8 | G14: =(128-E14)/128 | H14: =IF(D14=0,1,1-F14/D14)
A15: 1 | B15: 7 | C15: 0.9403 | D15: 130 | E15: 0 | F15: 2 | G15: =(128-E15)/128 | H15: =IF(D15=0,1,1-F15/D15)
A16: 1 | B16: 10 | C16: 0.941 | D16: 130 | E16: 2 | F16: 4 | G16: =(128-E16)/128 | H16: =IF(D16=0,1,1-F16/D16)
... A24: 5 | B24: 10 | C24: 0.9451 | D24: 124 | E24: 8 | F24: 4 | G24: =(128-E24)/128 | H24: =IF(D24=0,1,1-F24/D24)
A26: Reading it: at $0.00 every bank fee becomes an amount mismatch; at $5.00 the small short-pays are absorbed. At 2 days normal posting lag floods the queue; at 10 days genuine timing gaps are absorbed.
A27: Caveat: the 7-day knee reflects the synthetic posting lag (at most 6 days). With real data, set the date tolerance from the observed spread on cleanly matched items.
